<?xml version="1.0"?>
<robot name="generated_robot">
  <link name="base_link">
    <inertial>
      <origin xyz="0.00086111 -0.1813544 0.00770474" rpy="0 0 0"/>
      <mass value="0.70093924"/>
      <inertia ixx="0.00116811" ixy="0" ixz="0" iyy="0.00260125" iyz="0.00001864" izz="0.00264283"/>
    </inertial>
    <visual name="part_001_visual_1">
      <origin xyz="0 0 0" rpy="1.57079633 0 0"/>
      <geometry><mesh filename="meshes/part_001_NAUO1.stl" scale="0.001 0.001 0.001"/></geometry>
    </visual>
    <collision name="part_001_collision_1">
      <origin xyz="0 0 0" rpy="1.57079633 0 0"/>
      <geometry><mesh filename="meshes/part_001_NAUO1.stl" scale="0.001 0.001 0.001"/></geometry>
    </collision>
    <visual name="part_006_visual_2">
      <origin xyz="0 0 0" rpy="1.57079633 0 0"/>
      <geometry><mesh filename="meshes/part_006_NAUO6.stl" scale="0.001 0.001 0.001"/></geometry>
    </visual>
    <collision name="part_006_collision_2">
      <origin xyz="0 0 0" rpy="1.57079633 0 0"/>
      <geometry><mesh filename="meshes/part_006_NAUO6.stl" scale="0.001 0.001 0.001"/></geometry>
    </collision>
    <visual name="part_007_visual_3">
      <origin xyz="0 0 0" rpy="1.57079633 0 0"/>
      <geometry><mesh filename="meshes/part_007_NAUO7.stl" scale="0.001 0.001 0.001"/></geometry>
    </visual>
    <collision name="part_007_collision_3">
      <origin xyz="0 0 0" rpy="1.57079633 0 0"/>
      <geometry><mesh filename="meshes/part_007_NAUO7.stl" scale="0.001 0.001 0.001"/></geometry>
    </collision>
  </link>
  <link name="shoulder_link">
    <inertial>
      <origin xyz="0.0007691 -0.02782758 0.02477651" rpy="0 0 0"/>
      <mass value="0.23040249"/>
      <inertia ixx="0.00035548" ixy="7e-8" ixz="-3.6e-7" iyy="0.00030371" iyz="0.00002044" izz="0.00019188"/>
    </inertial>
    <visual name="part_002_visual_1">
      <origin xyz="-0.00012963 0.21966414 -0.02325593" rpy="1.57079633 0 0"/>
      <geometry><mesh filename="meshes/part_002_NAUO2.stl" scale="0.001 0.001 0.001"/></geometry>
    </visual>
    <collision name="part_002_collision_1">
      <origin xyz="-0.00012963 0.21966414 -0.02325593" rpy="1.57079633 0 0"/>
      <geometry><mesh filename="meshes/part_002_NAUO2.stl" scale="0.001 0.001 0.001"/></geometry>
    </collision>
    <visual name="part_003_visual_2">
      <origin xyz="-0.00012963 0.21966414 -0.02325593" rpy="1.57079633 0 0"/>
      <geometry><mesh filename="meshes/part_003_NAUO3.stl" scale="0.001 0.001 0.001"/></geometry>
    </visual>
    <collision name="part_003_collision_2">
      <origin xyz="-0.00012963 0.21966414 -0.02325593" rpy="1.57079633 0 0"/>
      <geometry><mesh filename="meshes/part_003_NAUO3.stl" scale="0.001 0.001 0.001"/></geometry>
    </collision>
    <visual name="part_008_visual_3">
      <origin xyz="-0.00012963 0.21966414 -0.02325593" rpy="1.57079633 0 0"/>
      <geometry><mesh filename="meshes/part_008_NAUO8.stl" scale="0.001 0.001 0.001"/></geometry>
    </visual>
    <collision name="part_008_collision_3">
      <origin xyz="-0.00012963 0.21966414 -0.02325593" rpy="1.57079633 0 0"/>
      <geometry><mesh filename="meshes/part_008_NAUO8.stl" scale="0.001 0.001 0.001"/></geometry>
    </collision>
  </link>
  <link name="upper_arm_link">
    <inertial>
      <origin xyz="0.00003407 -0.04347462 0.06639222" rpy="0 0 0"/>
      <mass value="0.25426906"/>
      <inertia ixx="0.00078548" ixy="3.5e-7" ixz="-3.1e-7" iyy="0.00062631" iyz="0.00004659" izz="0.00040959"/>
    </inertial>
    <visual name="part_009_visual_1">
      <origin xyz="-0.00081111 0.25501445 -0.10461329" rpy="1.57079633 0 0"/>
      <geometry><mesh filename="meshes/part_009_NAUO9.stl" scale="0.001 0.001 0.001"/></geometry>
    </visual>
    <collision name="part_009_collision_1">
      <origin xyz="-0.00081111 0.25501445 -0.10461329" rpy="1.57079633 0 0"/>
      <geometry><mesh filename="meshes/part_009_NAUO9.stl" scale="0.001 0.001 0.001"/></geometry>
    </collision>
    <visual name="part_010_visual_2">
      <origin xyz="-0.00081111 0.25501445 -0.10461329" rpy="1.57079633 0 0"/>
      <geometry><mesh filename="meshes/part_010_NAUO10.stl" scale="0.001 0.001 0.001"/></geometry>
    </visual>
    <collision name="part_010_collision_2">
      <origin xyz="-0.00081111 0.25501445 -0.10461329" rpy="1.57079633 0 0"/>
      <geometry><mesh filename="meshes/part_010_NAUO10.stl" scale="0.001 0.001 0.001"/></geometry>
    </collision>
  </link>
  <link name="lower_arm_link">
    <inertial>
      <origin xyz="0.0000288 -0.05928201 0.06981532" rpy="0 0 0"/>
      <mass value="0.3005256"/>
      <inertia ixx="0.00106467" ixy="3.4e-7" ixz="-4.6e-7" iyy="0.00075906" iyz="0.00013298" izz="0.00059397"/>
    </inertial>
    <visual name="part_011_visual_1">
      <origin xyz="-0.0007611 0.35118196 -0.19880969" rpy="1.57079633 0 0"/>
      <geometry><mesh filename="meshes/part_011_NAUO11.stl" scale="0.001 0.001 0.001"/></geometry>
    </visual>
    <collision name="part_011_collision_1">
      <origin xyz="-0.0007611 0.35118196 -0.19880969" rpy="1.57079633 0 0"/>
      <geometry><mesh filename="meshes/part_011_NAUO11.stl" scale="0.001 0.001 0.001"/></geometry>
    </collision>
    <visual name="part_004_visual_2">
      <origin xyz="-0.0007611 0.35118196 -0.19880969" rpy="1.57079633 0 0"/>
      <geometry><mesh filename="meshes/part_004_NAUO4.stl" scale="0.001 0.001 0.001"/></geometry>
    </visual>
    <collision name="part_004_collision_2">
      <origin xyz="-0.0007611 0.35118196 -0.19880969" rpy="1.57079633 0 0"/>
      <geometry><mesh filename="meshes/part_004_NAUO4.stl" scale="0.001 0.001 0.001"/></geometry>
    </collision>
    <visual name="part_012_visual_3">
      <origin xyz="-0.0007611 0.35118196 -0.19880969" rpy="1.57079633 0 0"/>
      <geometry><mesh filename="meshes/part_012_NAUO12.stl" scale="0.001 0.001 0.001"/></geometry>
    </visual>
    <collision name="part_012_collision_3">
      <origin xyz="-0.0007611 0.35118196 -0.19880969" rpy="1.57079633 0 0"/>
      <geometry><mesh filename="meshes/part_012_NAUO12.stl" scale="0.001 0.001 0.001"/></geometry>
    </collision>
  </link>
  <link name="wrist_link">
    <inertial>
      <origin xyz="-0.0013334 -0.03352803 0.04012786" rpy="0 0 0"/>
      <mass value="0.37513573"/>
      <inertia ixx="0.00031511" ixy="-0.00000184" ixz="0.00000277" iyy="0.00030999" iyz="0.00000805" izz="0.000283"/>
    </inertial>
    <visual name="part_005_visual_1">
      <origin xyz="-0.00021981 0.45984725 -0.33273312" rpy="1.57079633 0 0"/>
      <geometry><mesh filename="meshes/part_005_NAUO5.stl" scale="0.001 0.001 0.001"/></geometry>
    </visual>
    <collision name="part_005_collision_1">
      <origin xyz="-0.00021981 0.45984725 -0.33273312" rpy="1.57079633 0 0"/>
      <geometry><mesh filename="meshes/part_005_NAUO5.stl" scale="0.001 0.001 0.001"/></geometry>
    </collision>
    <visual name="part_013_visual_2">
      <origin xyz="-0.00021981 0.45984725 -0.33273312" rpy="1.57079633 0 0"/>
      <geometry><mesh filename="meshes/part_013_NAUO13.stl" scale="0.001 0.001 0.001"/></geometry>
    </visual>
    <collision name="part_013_collision_2">
      <origin xyz="-0.00021981 0.45984725 -0.33273312" rpy="1.57079633 0 0"/>
      <geometry><mesh filename="meshes/part_013_NAUO13.stl" scale="0.001 0.001 0.001"/></geometry>
    </collision>
  </link>
  <link name="grisp_link">
    <inertial>
      <origin xyz="0 -0.08860376 0.01764246" rpy="0 0 0"/>
      <mass value="0.04801739"/>
      <inertia ixx="0.00040537" ixy="0" ixz="0" iyy="0.00003848" iyz="0.00003947" izz="0.00040395"/>
    </inertial>
    <visual name="part_014_visual_1">
      <origin xyz="-0.01346111 0.51406831 -0.39912669" rpy="1.57079633 0 0"/>
      <geometry><mesh filename="meshes/part_014_NAUO14.stl" scale="0.001 0.001 0.001"/></geometry>
    </visual>
    <collision name="part_014_collision_1">
      <origin xyz="-0.01346111 0.51406831 -0.39912669" rpy="1.57079633 0 0"/>
      <geometry><mesh filename="meshes/part_014_NAUO14.stl" scale="0.001 0.001 0.001"/></geometry>
    </collision>
    <visual name="part_015_visual_2">
      <origin xyz="-0.01346111 0.51406831 -0.39912669" rpy="1.57079633 0 0"/>
      <geometry><mesh filename="meshes/part_015_NAUO15.stl" scale="0.001 0.001 0.001"/></geometry>
    </visual>
    <collision name="part_015_collision_2">
      <origin xyz="-0.01346111 0.51406831 -0.39912669" rpy="1.57079633 0 0"/>
      <geometry><mesh filename="meshes/part_015_NAUO15.stl" scale="0.001 0.001 0.001"/></geometry>
    </collision>
  </link>
  <joint name="shoulder_pan" type="revolute">
    <parent link="base_link"/>
    <child link="shoulder_link"/>
    <origin xyz="0.00012963 -0.21966414 0.02325593" rpy="0 0 0"/>
    <axis xyz="-0.02452301 0.01634245 -0.99956568"/>
    <limit lower="-1.92" upper="1.92" effort="10" velocity="5"/>
  </joint>
  <joint name="shoulder_lift" type="revolute">
    <parent link="shoulder_link"/>
    <child link="upper_arm_link"/>
    <origin xyz="0.00068148 -0.03535031 0.08135736" rpy="0 0 0"/>
    <axis xyz="0.999758 -0.01398021 0.01698535"/>
    <limit lower="-2.269" upper="1.047" effort="10" velocity="5"/>
  </joint>
  <joint name="elbow_flex" type="revolute">
    <parent link="upper_arm_link"/>
    <child link="lower_arm_link"/>
    <origin xyz="-0.00005 -0.09616751 0.0941964" rpy="0 0 0"/>
    <axis xyz="0.9999943 0.00206578 0.00266889"/>
    <limit lower="-0.175" upper="2.88" effort="10" velocity="5"/>
  </joint>
  <joint name="wrist_fliex" type="revolute">
    <parent link="lower_arm_link"/>
    <child link="wrist_link"/>
    <origin xyz="-0.0005413 -0.10866529 0.13392342" rpy="0 0 0"/>
    <axis xyz="0.99999207 0.00129384 0.00376768"/>
    <limit lower="-1.66" upper="1.66" effort="10" velocity="5"/>
  </joint>
  <joint name="wrist_roll" type="revolute">
    <parent link="wrist_link"/>
    <child link="grisp_link"/>
    <origin xyz="0.0132413 -0.05422106 0.06639357" rpy="0 0 0"/>
    <axis xyz="0 -0.62935133 0.77712091"/>
    <limit lower="-2.269" upper="2.269" effort="10" velocity="5"/>
  </joint>
</robot>
